package pl.sdacademy.unit.test.basic.exercises.unit.task5;

import org.junit.jupiter.api.BeforeAll;
import org.junit.jupiter.api.Test;

import static org.assertj.core.api.Assertions.assertThat;
import static org.assertj.core.api.Assertions.assertThatThrownBy;
import static org.junit.jupiter.api.Assertions.*;

class CalculatorWithExceptionTest {

    private static CalculatorWithException calculator;

    @BeforeAll
    static void init() {
        calculator = new CalculatorWithException();
    }

    @Test
    void shouldDivisionTwoValues() {
        //when
        float result = calculator.divide(6, 3);
        //then
        assertEquals(2, result);
        assertThat(result).isEqualTo(2);
    }

    @Test
    void shouldThrowExceptionIfSecondNumberIsEqualZero() {
        //#Option1 - junit5
        try {
            calculator.divide(2, 0);
            fail();
        } catch (ArithmeticException ex) {
            assertThat(ex).isInstanceOf(ArithmeticException.class)
                    .hasMessage("Cannot divide by zero!");
        }

        //#Option2 -junit5
        assertThrows(ArithmeticException.class,
                () -> calculator.divide(2, 0), "Cannot divide by zero!");

        //#Option3 - assertJ
        assertThatThrownBy(() -> calculator.divide(2, 0))
                .isInstanceOf(ArithmeticException.class)
                .hasMessage("Cannot divide by zero!");
    }
}